2024-04-15 10:55:40,013 -  nornir.core -     INFO -        run() - Running task 'load_variables' with args {'nr': <nornir.core.Nornir object at 0x7ff555205e80>} on 13 hosts
2024-04-15 10:55:47,154 - nornir.core.task -    ERROR -      start() - Host 'SPINE-HQ-1-5': task 'load_variables' failed with traceback:
Traceback (most recent call last):
  File "/root/cn6000_automation/.venv/lib/python3.8/site-packages/nornir/core/task.py", line 99, in start
    r = self.task(self, **self.params)
  File "configs_update.py", line 14, in load_variables
    test_templates(task, nr)
  File "configs_update.py", line 28, in test_templates
    result = task.run(task=send_configs, configs=configuration)
  File "/root/cn6000_automation/.venv/lib/python3.8/site-packages/nornir/core/task.py", line 174, in run
    raise NornirSubTaskError(task=run_task, result=r)
nornir.core.exceptions.NornirSubTaskError: Subtask: send_configs (failed)


2024-04-15 10:55:47,276 - nornir.core.task -    ERROR -      start() - Host 'SPINE-HQ-2-6': task 'load_variables' failed with traceback:
Traceback (most recent call last):
  File "/root/cn6000_automation/.venv/lib/python3.8/site-packages/nornir/core/task.py", line 99, in start
    r = self.task(self, **self.params)
  File "configs_update.py", line 14, in load_variables
    test_templates(task, nr)
  File "configs_update.py", line 28, in test_templates
    result = task.run(task=send_configs, configs=configuration)
  File "/root/cn6000_automation/.venv/lib/python3.8/site-packages/nornir/core/task.py", line 174, in run
    raise NornirSubTaskError(task=run_task, result=r)
nornir.core.exceptions.NornirSubTaskError: Subtask: send_configs (failed)


2024-04-15 10:58:01,048 -  nornir.core -     INFO -        run() - Running task 'load_variables' with args {'nr': <nornir.core.Nornir object at 0x7fe35614de20>} on 10 hosts
2024-04-15 10:58:07,118 - nornir.core.task -    ERROR -      start() - Host 'SPINE-HQ-1-5': task 'load_variables' failed with traceback:
Traceback (most recent call last):
  File "/root/cn6000_automation/.venv/lib/python3.8/site-packages/nornir/core/task.py", line 99, in start
    r = self.task(self, **self.params)
  File "configs_update.py", line 14, in load_variables
    test_templates(task, nr)
  File "configs_update.py", line 28, in test_templates
    result = task.run(task=send_configs, configs=configuration)
  File "/root/cn6000_automation/.venv/lib/python3.8/site-packages/nornir/core/task.py", line 174, in run
    raise NornirSubTaskError(task=run_task, result=r)
nornir.core.exceptions.NornirSubTaskError: Subtask: send_configs (failed)


2024-04-15 10:58:07,431 - nornir.core.task -    ERROR -      start() - Host 'SPINE-HQ-2-6': task 'load_variables' failed with traceback:
Traceback (most recent call last):
  File "/root/cn6000_automation/.venv/lib/python3.8/site-packages/nornir/core/task.py", line 99, in start
    r = self.task(self, **self.params)
  File "configs_update.py", line 14, in load_variables
    test_templates(task, nr)
  File "configs_update.py", line 28, in test_templates
    result = task.run(task=send_configs, configs=configuration)
  File "/root/cn6000_automation/.venv/lib/python3.8/site-packages/nornir/core/task.py", line 174, in run
    raise NornirSubTaskError(task=run_task, result=r)
nornir.core.exceptions.NornirSubTaskError: Subtask: send_configs (failed)


2024-04-15 11:12:36,277 -  nornir.core -     INFO -        run() - Running task 'connection_test' with args {} on 10 hosts
2024-04-15 11:12:39,391 - nornir.core.task -    ERROR -      start() - Host 'LEAF-HQ-3-4': task 'napalm_get' failed with traceback:
Traceback (most recent call last):
  File "/root/cn6000_automation/.venv/lib/python3.8/site-packages/netmiko/base_connection.py", line 1137, in establish_connection
    self.remote_conn_pre.connect(**ssh_connect_params)
  File "/root/cn6000_automation/.venv/lib/python3.8/site-packages/paramiko/client.py", line 409, in connect
    raise NoValidConnectionsError(errors)
paramiko.ssh_exception.NoValidConnectionsError: [Errno None] Unable to connect to port 22 on 172.16.10.4

During handling of the above exception, another exception occurred:

Traceback (most recent call last):
  File "/root/cn6000_automation/.venv/lib/python3.8/site-packages/napalm/base/base.py", line 114, in _netmiko_open
    self._netmiko_device = ConnectHandler(
  File "/root/cn6000_automation/.venv/lib/python3.8/site-packages/netmiko/ssh_dispatcher.py", line 399, in ConnectHandler
    return ConnectionClass(*args, **kwargs)
  File "/root/cn6000_automation/.venv/lib/python3.8/site-packages/netmiko/base_connection.py", line 488, in __init__
    self._open()
  File "/root/cn6000_automation/.venv/lib/python3.8/site-packages/netmiko/base_connection.py", line 493, in _open
    self.establish_connection()
  File "/root/cn6000_automation/.venv/lib/python3.8/site-packages/netmiko/base_connection.py", line 1159, in establish_connection
    raise NetmikoTimeoutException(msg)
netmiko.exceptions.NetmikoTimeoutException: TCP connection to device failed.

Common causes of this problem are:
1. Incorrect hostname or IP address.
2. Wrong TCP port.
3. Intermediate firewall blocking access.

Device settings: cisco_ios 172.16.10.4:22



During handling of the above exception, another exception occurred:

Traceback (most recent call last):
  File "/root/cn6000_automation/.venv/lib/python3.8/site-packages/nornir/core/task.py", line 99, in start
    r = self.task(self, **self.params)
  File "/root/cn6000_automation/.venv/lib/python3.8/site-packages/nornir_napalm/plugins/tasks/napalm_get.py", line 32, in napalm_get
    device = task.host.get_connection(CONNECTION_NAME, task.nornir.config)
  File "/root/cn6000_automation/.venv/lib/python3.8/site-packages/nornir/core/inventory.py", line 494, in get_connection
    self.open_connection(
  File "/root/cn6000_automation/.venv/lib/python3.8/site-packages/nornir/core/inventory.py", line 546, in open_connection
    conn_obj.open(
  File "/root/cn6000_automation/.venv/lib/python3.8/site-packages/nornir_napalm/plugins/connections/__init__.py", line 57, in open
    connection.open()
  File "/root/cn6000_automation/.venv/lib/python3.8/site-packages/napalm/ios/ios.py", line 172, in open
    self.device = self._netmiko_open(
  File "/root/cn6000_automation/.venv/lib/python3.8/site-packages/napalm/base/base.py", line 123, in _netmiko_open
    raise ConnectionException("Cannot connect to {}".format(self.hostname))
napalm.base.exceptions.ConnectionException: Cannot connect to 172.16.10.4

2024-04-15 11:12:39,392 - nornir.core.task -    ERROR -      start() - Host 'LEAF-HQ-1-2': task 'napalm_get' failed with traceback:
Traceback (most recent call last):
  File "/root/cn6000_automation/.venv/lib/python3.8/site-packages/pyeapi/eapilib.py", line 433, in send
    self.transport.endheaders(message_body=data)
  File "/usr/lib/python3.8/http/client.py", line 1251, in endheaders
    self._send_output(message_body, encode_chunked=encode_chunked)
  File "/usr/lib/python3.8/http/client.py", line 1011, in _send_output
    self.send(msg)
  File "/usr/lib/python3.8/http/client.py", line 951, in send
    self.connect()
  File "/usr/lib/python3.8/http/client.py", line 1418, in connect
    super().connect()
  File "/usr/lib/python3.8/http/client.py", line 922, in connect
    self.sock = self._create_connection(
  File "/usr/lib/python3.8/socket.py", line 808, in create_connection
    raise err
  File "/usr/lib/python3.8/socket.py", line 796, in create_connection
    sock.connect(sa)
OSError: [Errno 113] No route to host

During handling of the above exception, another exception occurred:

Traceback (most recent call last):
  File "/root/cn6000_automation/.venv/lib/python3.8/site-packages/napalm/eos/eos.py", line 223, in open
    sh_ver = self.device.run_commands(["show version"])
  File "/root/cn6000_automation/.venv/lib/python3.8/site-packages/napalm/eos/pyeapi_syntax_wrapper.py", line 42, in run_commands
    return super(Node, self).run_commands(commands, *args, **kwargs)
  File "/root/cn6000_automation/.venv/lib/python3.8/site-packages/pyeapi/client.py", line 887, in run_commands
    response = self._connection.execute(commands, encoding, **kwargs)
  File "/root/cn6000_automation/.venv/lib/python3.8/site-packages/pyeapi/eapilib.py", line 627, in execute
    response = self.send(request)
  File "/root/cn6000_automation/.venv/lib/python3.8/site-packages/pyeapi/eapilib.py", line 471, in send
    raise ConnectionError(str(self), error_msg)
pyeapi.eapilib.ConnectionError: Socket error during eAPI connection: [Errno 113] No route to host

During handling of the above exception, another exception occurred:

Traceback (most recent call last):
  File "/root/cn6000_automation/.venv/lib/python3.8/site-packages/nornir/core/task.py", line 99, in start
    r = self.task(self, **self.params)
  File "/root/cn6000_automation/.venv/lib/python3.8/site-packages/nornir_napalm/plugins/tasks/napalm_get.py", line 32, in napalm_get
    device = task.host.get_connection(CONNECTION_NAME, task.nornir.config)
  File "/root/cn6000_automation/.venv/lib/python3.8/site-packages/nornir/core/inventory.py", line 494, in get_connection
    self.open_connection(
  File "/root/cn6000_automation/.venv/lib/python3.8/site-packages/nornir/core/inventory.py", line 546, in open_connection
    conn_obj.open(
  File "/root/cn6000_automation/.venv/lib/python3.8/site-packages/nornir_napalm/plugins/connections/__init__.py", line 57, in open
    connection.open()
  File "/root/cn6000_automation/.venv/lib/python3.8/site-packages/napalm/eos/eos.py", line 233, in open
    raise ConnectionException(str(ce))
napalm.base.exceptions.ConnectionException: Socket error during eAPI connection: [Errno 113] No route to host

2024-04-15 11:12:39,443 - nornir.core.task -    ERROR -      start() - Host 'LEAF-HQ-2-3': task 'napalm_get' failed with traceback:
Traceback (most recent call last):
  File "/root/cn6000_automation/.venv/lib/python3.8/site-packages/pyeapi/eapilib.py", line 433, in send
    self.transport.endheaders(message_body=data)
  File "/usr/lib/python3.8/http/client.py", line 1251, in endheaders
    self._send_output(message_body, encode_chunked=encode_chunked)
  File "/usr/lib/python3.8/http/client.py", line 1011, in _send_output
    self.send(msg)
  File "/usr/lib/python3.8/http/client.py", line 951, in send
    self.connect()
  File "/usr/lib/python3.8/http/client.py", line 1418, in connect
    super().connect()
  File "/usr/lib/python3.8/http/client.py", line 922, in connect
    self.sock = self._create_connection(
  File "/usr/lib/python3.8/socket.py", line 808, in create_connection
    raise err
  File "/usr/lib/python3.8/socket.py", line 796, in create_connection
    sock.connect(sa)
OSError: [Errno 113] No route to host

During handling of the above exception, another exception occurred:

Traceback (most recent call last):
  File "/root/cn6000_automation/.venv/lib/python3.8/site-packages/napalm/eos/eos.py", line 223, in open
    sh_ver = self.device.run_commands(["show version"])
  File "/root/cn6000_automation/.venv/lib/python3.8/site-packages/napalm/eos/pyeapi_syntax_wrapper.py", line 42, in run_commands
    return super(Node, self).run_commands(commands, *args, **kwargs)
  File "/root/cn6000_automation/.venv/lib/python3.8/site-packages/pyeapi/client.py", line 887, in run_commands
    response = self._connection.execute(commands, encoding, **kwargs)
  File "/root/cn6000_automation/.venv/lib/python3.8/site-packages/pyeapi/eapilib.py", line 627, in execute
    response = self.send(request)
  File "/root/cn6000_automation/.venv/lib/python3.8/site-packages/pyeapi/eapilib.py", line 471, in send
    raise ConnectionError(str(self), error_msg)
pyeapi.eapilib.ConnectionError: Socket error during eAPI connection: [Errno 113] No route to host

During handling of the above exception, another exception occurred:

Traceback (most recent call last):
  File "/root/cn6000_automation/.venv/lib/python3.8/site-packages/nornir/core/task.py", line 99, in start
    r = self.task(self, **self.params)
  File "/root/cn6000_automation/.venv/lib/python3.8/site-packages/nornir_napalm/plugins/tasks/napalm_get.py", line 32, in napalm_get
    device = task.host.get_connection(CONNECTION_NAME, task.nornir.config)
  File "/root/cn6000_automation/.venv/lib/python3.8/site-packages/nornir/core/inventory.py", line 494, in get_connection
    self.open_connection(
  File "/root/cn6000_automation/.venv/lib/python3.8/site-packages/nornir/core/inventory.py", line 546, in open_connection
    conn_obj.open(
  File "/root/cn6000_automation/.venv/lib/python3.8/site-packages/nornir_napalm/plugins/connections/__init__.py", line 57, in open
    connection.open()
  File "/root/cn6000_automation/.venv/lib/python3.8/site-packages/napalm/eos/eos.py", line 233, in open
    raise ConnectionException(str(ce))
napalm.base.exceptions.ConnectionException: Socket error during eAPI connection: [Errno 113] No route to host

2024-04-15 11:24:33,604 -  nornir.core -     INFO -        run() - Running task 'connection_test' with args {} on 10 hosts
2024-04-15 11:24:36,694 - nornir.core.task -    ERROR -      start() - Host 'LEAF-HQ-1-2': task 'napalm_get' failed with traceback:
Traceback (most recent call last):
  File "/root/cn6000_automation/.venv/lib/python3.8/site-packages/pyeapi/eapilib.py", line 433, in send
    self.transport.endheaders(message_body=data)
  File "/usr/lib/python3.8/http/client.py", line 1251, in endheaders
    self._send_output(message_body, encode_chunked=encode_chunked)
  File "/usr/lib/python3.8/http/client.py", line 1011, in _send_output
    self.send(msg)
  File "/usr/lib/python3.8/http/client.py", line 951, in send
    self.connect()
  File "/usr/lib/python3.8/http/client.py", line 1418, in connect
    super().connect()
  File "/usr/lib/python3.8/http/client.py", line 922, in connect
    self.sock = self._create_connection(
  File "/usr/lib/python3.8/socket.py", line 808, in create_connection
    raise err
  File "/usr/lib/python3.8/socket.py", line 796, in create_connection
    sock.connect(sa)
OSError: [Errno 113] No route to host

During handling of the above exception, another exception occurred:

Traceback (most recent call last):
  File "/root/cn6000_automation/.venv/lib/python3.8/site-packages/napalm/eos/eos.py", line 223, in open
    sh_ver = self.device.run_commands(["show version"])
  File "/root/cn6000_automation/.venv/lib/python3.8/site-packages/napalm/eos/pyeapi_syntax_wrapper.py", line 42, in run_commands
    return super(Node, self).run_commands(commands, *args, **kwargs)
  File "/root/cn6000_automation/.venv/lib/python3.8/site-packages/pyeapi/client.py", line 887, in run_commands
    response = self._connection.execute(commands, encoding, **kwargs)
  File "/root/cn6000_automation/.venv/lib/python3.8/site-packages/pyeapi/eapilib.py", line 627, in execute
    response = self.send(request)
  File "/root/cn6000_automation/.venv/lib/python3.8/site-packages/pyeapi/eapilib.py", line 471, in send
    raise ConnectionError(str(self), error_msg)
pyeapi.eapilib.ConnectionError: Socket error during eAPI connection: [Errno 113] No route to host

During handling of the above exception, another exception occurred:

Traceback (most recent call last):
  File "/root/cn6000_automation/.venv/lib/python3.8/site-packages/nornir/core/task.py", line 99, in start
    r = self.task(self, **self.params)
  File "/root/cn6000_automation/.venv/lib/python3.8/site-packages/nornir_napalm/plugins/tasks/napalm_get.py", line 32, in napalm_get
    device = task.host.get_connection(CONNECTION_NAME, task.nornir.config)
  File "/root/cn6000_automation/.venv/lib/python3.8/site-packages/nornir/core/inventory.py", line 494, in get_connection
    self.open_connection(
  File "/root/cn6000_automation/.venv/lib/python3.8/site-packages/nornir/core/inventory.py", line 546, in open_connection
    conn_obj.open(
  File "/root/cn6000_automation/.venv/lib/python3.8/site-packages/nornir_napalm/plugins/connections/__init__.py", line 57, in open
    connection.open()
  File "/root/cn6000_automation/.venv/lib/python3.8/site-packages/napalm/eos/eos.py", line 233, in open
    raise ConnectionException(str(ce))
napalm.base.exceptions.ConnectionException: Socket error during eAPI connection: [Errno 113] No route to host

2024-04-15 11:24:36,698 - nornir.core.task -    ERROR -      start() - Host 'LEAF-HQ-3-4': task 'napalm_get' failed with traceback:
Traceback (most recent call last):
  File "/root/cn6000_automation/.venv/lib/python3.8/site-packages/netmiko/base_connection.py", line 1137, in establish_connection
    self.remote_conn_pre.connect(**ssh_connect_params)
  File "/root/cn6000_automation/.venv/lib/python3.8/site-packages/paramiko/client.py", line 409, in connect
    raise NoValidConnectionsError(errors)
paramiko.ssh_exception.NoValidConnectionsError: [Errno None] Unable to connect to port 22 on 172.16.10.4

During handling of the above exception, another exception occurred:

Traceback (most recent call last):
  File "/root/cn6000_automation/.venv/lib/python3.8/site-packages/napalm/base/base.py", line 114, in _netmiko_open
    self._netmiko_device = ConnectHandler(
  File "/root/cn6000_automation/.venv/lib/python3.8/site-packages/netmiko/ssh_dispatcher.py", line 399, in ConnectHandler
    return ConnectionClass(*args, **kwargs)
  File "/root/cn6000_automation/.venv/lib/python3.8/site-packages/netmiko/base_connection.py", line 488, in __init__
    self._open()
  File "/root/cn6000_automation/.venv/lib/python3.8/site-packages/netmiko/base_connection.py", line 493, in _open
    self.establish_connection()
  File "/root/cn6000_automation/.venv/lib/python3.8/site-packages/netmiko/base_connection.py", line 1159, in establish_connection
    raise NetmikoTimeoutException(msg)
netmiko.exceptions.NetmikoTimeoutException: TCP connection to device failed.

Common causes of this problem are:
1. Incorrect hostname or IP address.
2. Wrong TCP port.
3. Intermediate firewall blocking access.

Device settings: cisco_ios 172.16.10.4:22



During handling of the above exception, another exception occurred:

Traceback (most recent call last):
  File "/root/cn6000_automation/.venv/lib/python3.8/site-packages/nornir/core/task.py", line 99, in start
    r = self.task(self, **self.params)
  File "/root/cn6000_automation/.venv/lib/python3.8/site-packages/nornir_napalm/plugins/tasks/napalm_get.py", line 32, in napalm_get
    device = task.host.get_connection(CONNECTION_NAME, task.nornir.config)
  File "/root/cn6000_automation/.venv/lib/python3.8/site-packages/nornir/core/inventory.py", line 494, in get_connection
    self.open_connection(
  File "/root/cn6000_automation/.venv/lib/python3.8/site-packages/nornir/core/inventory.py", line 546, in open_connection
    conn_obj.open(
  File "/root/cn6000_automation/.venv/lib/python3.8/site-packages/nornir_napalm/plugins/connections/__init__.py", line 57, in open
    connection.open()
  File "/root/cn6000_automation/.venv/lib/python3.8/site-packages/napalm/ios/ios.py", line 172, in open
    self.device = self._netmiko_open(
  File "/root/cn6000_automation/.venv/lib/python3.8/site-packages/napalm/base/base.py", line 123, in _netmiko_open
    raise ConnectionException("Cannot connect to {}".format(self.hostname))
napalm.base.exceptions.ConnectionException: Cannot connect to 172.16.10.4

2024-04-15 11:24:36,698 - nornir.core.task -    ERROR -      start() - Host 'SPINE-HQ-2-6': task 'napalm_get' failed with traceback:
Traceback (most recent call last):
  File "/root/cn6000_automation/.venv/lib/python3.8/site-packages/netmiko/base_connection.py", line 1137, in establish_connection
    self.remote_conn_pre.connect(**ssh_connect_params)
  File "/root/cn6000_automation/.venv/lib/python3.8/site-packages/paramiko/client.py", line 409, in connect
    raise NoValidConnectionsError(errors)
paramiko.ssh_exception.NoValidConnectionsError: [Errno None] Unable to connect to port 22 on 172.16.10.6

During handling of the above exception, another exception occurred:

Traceback (most recent call last):
  File "/root/cn6000_automation/.venv/lib/python3.8/site-packages/napalm/base/base.py", line 114, in _netmiko_open
    self._netmiko_device = ConnectHandler(
  File "/root/cn6000_automation/.venv/lib/python3.8/site-packages/netmiko/ssh_dispatcher.py", line 399, in ConnectHandler
    return ConnectionClass(*args, **kwargs)
  File "/root/cn6000_automation/.venv/lib/python3.8/site-packages/netmiko/base_connection.py", line 488, in __init__
    self._open()
  File "/root/cn6000_automation/.venv/lib/python3.8/site-packages/netmiko/base_connection.py", line 493, in _open
    self.establish_connection()
  File "/root/cn6000_automation/.venv/lib/python3.8/site-packages/netmiko/base_connection.py", line 1159, in establish_connection
    raise NetmikoTimeoutException(msg)
netmiko.exceptions.NetmikoTimeoutException: TCP connection to device failed.

Common causes of this problem are:
1. Incorrect hostname or IP address.
2. Wrong TCP port.
3. Intermediate firewall blocking access.

Device settings: cisco_ios 172.16.10.6:22



During handling of the above exception, another exception occurred:

Traceback (most recent call last):
  File "/root/cn6000_automation/.venv/lib/python3.8/site-packages/nornir/core/task.py", line 99, in start
    r = self.task(self, **self.params)
  File "/root/cn6000_automation/.venv/lib/python3.8/site-packages/nornir_napalm/plugins/tasks/napalm_get.py", line 32, in napalm_get
    device = task.host.get_connection(CONNECTION_NAME, task.nornir.config)
  File "/root/cn6000_automation/.venv/lib/python3.8/site-packages/nornir/core/inventory.py", line 494, in get_connection
    self.open_connection(
  File "/root/cn6000_automation/.venv/lib/python3.8/site-packages/nornir/core/inventory.py", line 546, in open_connection
    conn_obj.open(
  File "/root/cn6000_automation/.venv/lib/python3.8/site-packages/nornir_napalm/plugins/connections/__init__.py", line 57, in open
    connection.open()
  File "/root/cn6000_automation/.venv/lib/python3.8/site-packages/napalm/ios/ios.py", line 172, in open
    self.device = self._netmiko_open(
  File "/root/cn6000_automation/.venv/lib/python3.8/site-packages/napalm/base/base.py", line 123, in _netmiko_open
    raise ConnectionException("Cannot connect to {}".format(self.hostname))
napalm.base.exceptions.ConnectionException: Cannot connect to 172.16.10.6

2024-04-15 11:24:36,699 - nornir.core.task -    ERROR -      start() - Host 'SPINE-HQ-1-5': task 'napalm_get' failed with traceback:
Traceback (most recent call last):
  File "/root/cn6000_automation/.venv/lib/python3.8/site-packages/netmiko/base_connection.py", line 1137, in establish_connection
    self.remote_conn_pre.connect(**ssh_connect_params)
  File "/root/cn6000_automation/.venv/lib/python3.8/site-packages/paramiko/client.py", line 409, in connect
    raise NoValidConnectionsError(errors)
paramiko.ssh_exception.NoValidConnectionsError: [Errno None] Unable to connect to port 22 on 172.16.10.5

During handling of the above exception, another exception occurred:

Traceback (most recent call last):
  File "/root/cn6000_automation/.venv/lib/python3.8/site-packages/napalm/base/base.py", line 114, in _netmiko_open
    self._netmiko_device = ConnectHandler(
  File "/root/cn6000_automation/.venv/lib/python3.8/site-packages/netmiko/ssh_dispatcher.py", line 399, in ConnectHandler
    return ConnectionClass(*args, **kwargs)
  File "/root/cn6000_automation/.venv/lib/python3.8/site-packages/netmiko/base_connection.py", line 488, in __init__
    self._open()
  File "/root/cn6000_automation/.venv/lib/python3.8/site-packages/netmiko/base_connection.py", line 493, in _open
    self.establish_connection()
  File "/root/cn6000_automation/.venv/lib/python3.8/site-packages/netmiko/base_connection.py", line 1159, in establish_connection
    raise NetmikoTimeoutException(msg)
netmiko.exceptions.NetmikoTimeoutException: TCP connection to device failed.

Common causes of this problem are:
1. Incorrect hostname or IP address.
2. Wrong TCP port.
3. Intermediate firewall blocking access.

Device settings: cisco_ios 172.16.10.5:22



During handling of the above exception, another exception occurred:

Traceback (most recent call last):
  File "/root/cn6000_automation/.venv/lib/python3.8/site-packages/nornir/core/task.py", line 99, in start
    r = self.task(self, **self.params)
  File "/root/cn6000_automation/.venv/lib/python3.8/site-packages/nornir_napalm/plugins/tasks/napalm_get.py", line 32, in napalm_get
    device = task.host.get_connection(CONNECTION_NAME, task.nornir.config)
  File "/root/cn6000_automation/.venv/lib/python3.8/site-packages/nornir/core/inventory.py", line 494, in get_connection
    self.open_connection(
  File "/root/cn6000_automation/.venv/lib/python3.8/site-packages/nornir/core/inventory.py", line 546, in open_connection
    conn_obj.open(
  File "/root/cn6000_automation/.venv/lib/python3.8/site-packages/nornir_napalm/plugins/connections/__init__.py", line 57, in open
    connection.open()
  File "/root/cn6000_automation/.venv/lib/python3.8/site-packages/napalm/ios/ios.py", line 172, in open
    self.device = self._netmiko_open(
  File "/root/cn6000_automation/.venv/lib/python3.8/site-packages/napalm/base/base.py", line 123, in _netmiko_open
    raise ConnectionException("Cannot connect to {}".format(self.hostname))
napalm.base.exceptions.ConnectionException: Cannot connect to 172.16.10.5

2024-04-15 11:24:36,699 - nornir.core.task -    ERROR -      start() - Host 'ISP-CORE-6': task 'napalm_get' failed with traceback:
Traceback (most recent call last):
  File "/root/cn6000_automation/.venv/lib/python3.8/site-packages/netmiko/base_connection.py", line 1137, in establish_connection
    self.remote_conn_pre.connect(**ssh_connect_params)
  File "/root/cn6000_automation/.venv/lib/python3.8/site-packages/paramiko/client.py", line 409, in connect
    raise NoValidConnectionsError(errors)
paramiko.ssh_exception.NoValidConnectionsError: [Errno None] Unable to connect to port 22 on 192.168.10.6

During handling of the above exception, another exception occurred:

Traceback (most recent call last):
  File "/root/cn6000_automation/.venv/lib/python3.8/site-packages/napalm/base/base.py", line 114, in _netmiko_open
    self._netmiko_device = ConnectHandler(
  File "/root/cn6000_automation/.venv/lib/python3.8/site-packages/netmiko/ssh_dispatcher.py", line 399, in ConnectHandler
    return ConnectionClass(*args, **kwargs)
  File "/root/cn6000_automation/.venv/lib/python3.8/site-packages/netmiko/base_connection.py", line 488, in __init__
    self._open()
  File "/root/cn6000_automation/.venv/lib/python3.8/site-packages/netmiko/base_connection.py", line 493, in _open
    self.establish_connection()
  File "/root/cn6000_automation/.venv/lib/python3.8/site-packages/netmiko/base_connection.py", line 1159, in establish_connection
    raise NetmikoTimeoutException(msg)
netmiko.exceptions.NetmikoTimeoutException: TCP connection to device failed.

Common causes of this problem are:
1. Incorrect hostname or IP address.
2. Wrong TCP port.
3. Intermediate firewall blocking access.

Device settings: cisco_ios 192.168.10.6:22



During handling of the above exception, another exception occurred:

Traceback (most recent call last):
  File "/root/cn6000_automation/.venv/lib/python3.8/site-packages/nornir/core/task.py", line 99, in start
    r = self.task(self, **self.params)
  File "/root/cn6000_automation/.venv/lib/python3.8/site-packages/nornir_napalm/plugins/tasks/napalm_get.py", line 32, in napalm_get
    device = task.host.get_connection(CONNECTION_NAME, task.nornir.config)
  File "/root/cn6000_automation/.venv/lib/python3.8/site-packages/nornir/core/inventory.py", line 494, in get_connection
    self.open_connection(
  File "/root/cn6000_automation/.venv/lib/python3.8/site-packages/nornir/core/inventory.py", line 546, in open_connection
    conn_obj.open(
  File "/root/cn6000_automation/.venv/lib/python3.8/site-packages/nornir_napalm/plugins/connections/__init__.py", line 57, in open
    connection.open()
  File "/root/cn6000_automation/.venv/lib/python3.8/site-packages/napalm/ios/ios.py", line 172, in open
    self.device = self._netmiko_open(
  File "/root/cn6000_automation/.venv/lib/python3.8/site-packages/napalm/base/base.py", line 123, in _netmiko_open
    raise ConnectionException("Cannot connect to {}".format(self.hostname))
napalm.base.exceptions.ConnectionException: Cannot connect to 192.168.10.6

2024-04-15 11:24:36,700 - nornir.core.task -    ERROR -      start() - Host 'LEAF-HQ-2-3': task 'napalm_get' failed with traceback:
Traceback (most recent call last):
  File "/root/cn6000_automation/.venv/lib/python3.8/site-packages/pyeapi/eapilib.py", line 433, in send
    self.transport.endheaders(message_body=data)
  File "/usr/lib/python3.8/http/client.py", line 1251, in endheaders
    self._send_output(message_body, encode_chunked=encode_chunked)
  File "/usr/lib/python3.8/http/client.py", line 1011, in _send_output
    self.send(msg)
  File "/usr/lib/python3.8/http/client.py", line 951, in send
    self.connect()
  File "/usr/lib/python3.8/http/client.py", line 1418, in connect
    super().connect()
  File "/usr/lib/python3.8/http/client.py", line 922, in connect
    self.sock = self._create_connection(
  File "/usr/lib/python3.8/socket.py", line 808, in create_connection
    raise err
  File "/usr/lib/python3.8/socket.py", line 796, in create_connection
    sock.connect(sa)
OSError: [Errno 113] No route to host

During handling of the above exception, another exception occurred:

Traceback (most recent call last):
  File "/root/cn6000_automation/.venv/lib/python3.8/site-packages/napalm/eos/eos.py", line 223, in open
    sh_ver = self.device.run_commands(["show version"])
  File "/root/cn6000_automation/.venv/lib/python3.8/site-packages/napalm/eos/pyeapi_syntax_wrapper.py", line 42, in run_commands
    return super(Node, self).run_commands(commands, *args, **kwargs)
  File "/root/cn6000_automation/.venv/lib/python3.8/site-packages/pyeapi/client.py", line 887, in run_commands
    response = self._connection.execute(commands, encoding, **kwargs)
  File "/root/cn6000_automation/.venv/lib/python3.8/site-packages/pyeapi/eapilib.py", line 627, in execute
    response = self.send(request)
  File "/root/cn6000_automation/.venv/lib/python3.8/site-packages/pyeapi/eapilib.py", line 471, in send
    raise ConnectionError(str(self), error_msg)
pyeapi.eapilib.ConnectionError: Socket error during eAPI connection: [Errno 113] No route to host

During handling of the above exception, another exception occurred:

Traceback (most recent call last):
  File "/root/cn6000_automation/.venv/lib/python3.8/site-packages/nornir/core/task.py", line 99, in start
    r = self.task(self, **self.params)
  File "/root/cn6000_automation/.venv/lib/python3.8/site-packages/nornir_napalm/plugins/tasks/napalm_get.py", line 32, in napalm_get
    device = task.host.get_connection(CONNECTION_NAME, task.nornir.config)
  File "/root/cn6000_automation/.venv/lib/python3.8/site-packages/nornir/core/inventory.py", line 494, in get_connection
    self.open_connection(
  File "/root/cn6000_automation/.venv/lib/python3.8/site-packages/nornir/core/inventory.py", line 546, in open_connection
    conn_obj.open(
  File "/root/cn6000_automation/.venv/lib/python3.8/site-packages/nornir_napalm/plugins/connections/__init__.py", line 57, in open
    connection.open()
  File "/root/cn6000_automation/.venv/lib/python3.8/site-packages/napalm/eos/eos.py", line 233, in open
    raise ConnectionException(str(ce))
napalm.base.exceptions.ConnectionException: Socket error during eAPI connection: [Errno 113] No route to host

2024-04-15 11:27:22,349 -  nornir.core -     INFO -        run() - Running task 'connection_test' with args {} on 10 hosts
2024-04-15 11:27:25,429 - nornir.core.task -    ERROR -      start() - Host 'LEAF-HQ-2-3': task 'napalm_get' failed with traceback:
Traceback (most recent call last):
  File "/root/cn6000_automation/.venv/lib/python3.8/site-packages/pyeapi/eapilib.py", line 433, in send
    self.transport.endheaders(message_body=data)
  File "/usr/lib/python3.8/http/client.py", line 1251, in endheaders
    self._send_output(message_body, encode_chunked=encode_chunked)
  File "/usr/lib/python3.8/http/client.py", line 1011, in _send_output
    self.send(msg)
  File "/usr/lib/python3.8/http/client.py", line 951, in send
    self.connect()
  File "/usr/lib/python3.8/http/client.py", line 1418, in connect
    super().connect()
  File "/usr/lib/python3.8/http/client.py", line 922, in connect
    self.sock = self._create_connection(
  File "/usr/lib/python3.8/socket.py", line 808, in create_connection
    raise err
  File "/usr/lib/python3.8/socket.py", line 796, in create_connection
    sock.connect(sa)
OSError: [Errno 113] No route to host

During handling of the above exception, another exception occurred:

Traceback (most recent call last):
  File "/root/cn6000_automation/.venv/lib/python3.8/site-packages/napalm/eos/eos.py", line 223, in open
    sh_ver = self.device.run_commands(["show version"])
  File "/root/cn6000_automation/.venv/lib/python3.8/site-packages/napalm/eos/pyeapi_syntax_wrapper.py", line 42, in run_commands
    return super(Node, self).run_commands(commands, *args, **kwargs)
  File "/root/cn6000_automation/.venv/lib/python3.8/site-packages/pyeapi/client.py", line 887, in run_commands
    response = self._connection.execute(commands, encoding, **kwargs)
  File "/root/cn6000_automation/.venv/lib/python3.8/site-packages/pyeapi/eapilib.py", line 627, in execute
    response = self.send(request)
  File "/root/cn6000_automation/.venv/lib/python3.8/site-packages/pyeapi/eapilib.py", line 471, in send
    raise ConnectionError(str(self), error_msg)
pyeapi.eapilib.ConnectionError: Socket error during eAPI connection: [Errno 113] No route to host

During handling of the above exception, another exception occurred:

Traceback (most recent call last):
  File "/root/cn6000_automation/.venv/lib/python3.8/site-packages/nornir/core/task.py", line 99, in start
    r = self.task(self, **self.params)
  File "/root/cn6000_automation/.venv/lib/python3.8/site-packages/nornir_napalm/plugins/tasks/napalm_get.py", line 32, in napalm_get
    device = task.host.get_connection(CONNECTION_NAME, task.nornir.config)
  File "/root/cn6000_automation/.venv/lib/python3.8/site-packages/nornir/core/inventory.py", line 494, in get_connection
    self.open_connection(
  File "/root/cn6000_automation/.venv/lib/python3.8/site-packages/nornir/core/inventory.py", line 546, in open_connection
    conn_obj.open(
  File "/root/cn6000_automation/.venv/lib/python3.8/site-packages/nornir_napalm/plugins/connections/__init__.py", line 57, in open
    connection.open()
  File "/root/cn6000_automation/.venv/lib/python3.8/site-packages/napalm/eos/eos.py", line 233, in open
    raise ConnectionException(str(ce))
napalm.base.exceptions.ConnectionException: Socket error during eAPI connection: [Errno 113] No route to host

2024-04-15 11:27:25,493 - nornir.core.task -    ERROR -      start() - Host 'ISP-CORE-6': task 'napalm_get' failed with traceback:
Traceback (most recent call last):
  File "/root/cn6000_automation/.venv/lib/python3.8/site-packages/netmiko/base_connection.py", line 1137, in establish_connection
    self.remote_conn_pre.connect(**ssh_connect_params)
  File "/root/cn6000_automation/.venv/lib/python3.8/site-packages/paramiko/client.py", line 409, in connect
    raise NoValidConnectionsError(errors)
paramiko.ssh_exception.NoValidConnectionsError: [Errno None] Unable to connect to port 22 on 192.168.10.6

During handling of the above exception, another exception occurred:

Traceback (most recent call last):
  File "/root/cn6000_automation/.venv/lib/python3.8/site-packages/napalm/base/base.py", line 114, in _netmiko_open
    self._netmiko_device = ConnectHandler(
  File "/root/cn6000_automation/.venv/lib/python3.8/site-packages/netmiko/ssh_dispatcher.py", line 399, in ConnectHandler
    return ConnectionClass(*args, **kwargs)
  File "/root/cn6000_automation/.venv/lib/python3.8/site-packages/netmiko/base_connection.py", line 488, in __init__
    self._open()
  File "/root/cn6000_automation/.venv/lib/python3.8/site-packages/netmiko/base_connection.py", line 493, in _open
    self.establish_connection()
  File "/root/cn6000_automation/.venv/lib/python3.8/site-packages/netmiko/base_connection.py", line 1159, in establish_connection
    raise NetmikoTimeoutException(msg)
netmiko.exceptions.NetmikoTimeoutException: TCP connection to device failed.

Common causes of this problem are:
1. Incorrect hostname or IP address.
2. Wrong TCP port.
3. Intermediate firewall blocking access.

Device settings: cisco_ios 192.168.10.6:22



During handling of the above exception, another exception occurred:

Traceback (most recent call last):
  File "/root/cn6000_automation/.venv/lib/python3.8/site-packages/nornir/core/task.py", line 99, in start
    r = self.task(self, **self.params)
  File "/root/cn6000_automation/.venv/lib/python3.8/site-packages/nornir_napalm/plugins/tasks/napalm_get.py", line 32, in napalm_get
    device = task.host.get_connection(CONNECTION_NAME, task.nornir.config)
  File "/root/cn6000_automation/.venv/lib/python3.8/site-packages/nornir/core/inventory.py", line 494, in get_connection
    self.open_connection(
  File "/root/cn6000_automation/.venv/lib/python3.8/site-packages/nornir/core/inventory.py", line 546, in open_connection
    conn_obj.open(
  File "/root/cn6000_automation/.venv/lib/python3.8/site-packages/nornir_napalm/plugins/connections/__init__.py", line 57, in open
    connection.open()
  File "/root/cn6000_automation/.venv/lib/python3.8/site-packages/napalm/ios/ios.py", line 172, in open
    self.device = self._netmiko_open(
  File "/root/cn6000_automation/.venv/lib/python3.8/site-packages/napalm/base/base.py", line 123, in _netmiko_open
    raise ConnectionException("Cannot connect to {}".format(self.hostname))
napalm.base.exceptions.ConnectionException: Cannot connect to 192.168.10.6

2024-04-15 11:32:02,614 -  nornir.core -     INFO -        run() - Running task 'connection_test' with args {} on 10 hosts
2024-04-15 11:32:05,717 - nornir.core.task -    ERROR -      start() - Host 'ISP-CORE-6': task 'napalm_get' failed with traceback:
Traceback (most recent call last):
  File "/root/cn6000_automation/.venv/lib/python3.8/site-packages/netmiko/base_connection.py", line 1137, in establish_connection
    self.remote_conn_pre.connect(**ssh_connect_params)
  File "/root/cn6000_automation/.venv/lib/python3.8/site-packages/paramiko/client.py", line 409, in connect
    raise NoValidConnectionsError(errors)
paramiko.ssh_exception.NoValidConnectionsError: [Errno None] Unable to connect to port 22 on 192.168.10.6

During handling of the above exception, another exception occurred:

Traceback (most recent call last):
  File "/root/cn6000_automation/.venv/lib/python3.8/site-packages/napalm/base/base.py", line 114, in _netmiko_open
    self._netmiko_device = ConnectHandler(
  File "/root/cn6000_automation/.venv/lib/python3.8/site-packages/netmiko/ssh_dispatcher.py", line 399, in ConnectHandler
    return ConnectionClass(*args, **kwargs)
  File "/root/cn6000_automation/.venv/lib/python3.8/site-packages/netmiko/base_connection.py", line 488, in __init__
    self._open()
  File "/root/cn6000_automation/.venv/lib/python3.8/site-packages/netmiko/base_connection.py", line 493, in _open
    self.establish_connection()
  File "/root/cn6000_automation/.venv/lib/python3.8/site-packages/netmiko/base_connection.py", line 1159, in establish_connection
    raise NetmikoTimeoutException(msg)
netmiko.exceptions.NetmikoTimeoutException: TCP connection to device failed.

Common causes of this problem are:
1. Incorrect hostname or IP address.
2. Wrong TCP port.
3. Intermediate firewall blocking access.

Device settings: cisco_ios 192.168.10.6:22



During handling of the above exception, another exception occurred:

Traceback (most recent call last):
  File "/root/cn6000_automation/.venv/lib/python3.8/site-packages/nornir/core/task.py", line 99, in start
    r = self.task(self, **self.params)
  File "/root/cn6000_automation/.venv/lib/python3.8/site-packages/nornir_napalm/plugins/tasks/napalm_get.py", line 32, in napalm_get
    device = task.host.get_connection(CONNECTION_NAME, task.nornir.config)
  File "/root/cn6000_automation/.venv/lib/python3.8/site-packages/nornir/core/inventory.py", line 494, in get_connection
    self.open_connection(
  File "/root/cn6000_automation/.venv/lib/python3.8/site-packages/nornir/core/inventory.py", line 546, in open_connection
    conn_obj.open(
  File "/root/cn6000_automation/.venv/lib/python3.8/site-packages/nornir_napalm/plugins/connections/__init__.py", line 57, in open
    connection.open()
  File "/root/cn6000_automation/.venv/lib/python3.8/site-packages/napalm/ios/ios.py", line 172, in open
    self.device = self._netmiko_open(
  File "/root/cn6000_automation/.venv/lib/python3.8/site-packages/napalm/base/base.py", line 123, in _netmiko_open
    raise ConnectionException("Cannot connect to {}".format(self.hostname))
napalm.base.exceptions.ConnectionException: Cannot connect to 192.168.10.6

2024-04-15 11:32:26,613 -  nornir.core -     INFO -        run() - Running task 'connection_test' with args {} on 9 hosts
2024-04-15 11:32:47,741 -  nornir.core -     INFO -        run() - Running task 'connection_test' with args {} on 9 hosts
2024-04-15 11:32:49,261 -  nornir.core -     INFO -        run() - Running task 'backup_current_configs' with args {'backup_folder': 'backup_configs/20240415_113247'} on 9 hosts
2024-04-15 11:32:52,048 -  nornir.core -     INFO -        run() - Running task 'load_variables' with args {'nr': <nornir.core.Nornir object at 0x7fccaf3f5f70>} on 9 hosts
2024-04-15 11:32:57,877 - nornir.core.task -    ERROR -      start() - Host 'SPINE-HQ-1-5': task 'load_variables' failed with traceback:
Traceback (most recent call last):
  File "/root/cn6000_automation/.venv/lib/python3.8/site-packages/nornir/core/task.py", line 99, in start
    r = self.task(self, **self.params)
  File "/root/cn6000_automation/runbooks/configs_update.py", line 14, in load_variables
    test_templates(task, nr)
  File "/root/cn6000_automation/runbooks/configs_update.py", line 28, in test_templates
    result = task.run(task=send_configs, configs=configuration)
  File "/root/cn6000_automation/.venv/lib/python3.8/site-packages/nornir/core/task.py", line 174, in run
    raise NornirSubTaskError(task=run_task, result=r)
nornir.core.exceptions.NornirSubTaskError: Subtask: send_configs (failed)


2024-04-15 11:32:58,453 - nornir.core.task -    ERROR -      start() - Host 'SPINE-HQ-2-6': task 'load_variables' failed with traceback:
Traceback (most recent call last):
  File "/root/cn6000_automation/.venv/lib/python3.8/site-packages/nornir/core/task.py", line 99, in start
    r = self.task(self, **self.params)
  File "/root/cn6000_automation/runbooks/configs_update.py", line 14, in load_variables
    test_templates(task, nr)
  File "/root/cn6000_automation/runbooks/configs_update.py", line 28, in test_templates
    result = task.run(task=send_configs, configs=configuration)
  File "/root/cn6000_automation/.venv/lib/python3.8/site-packages/nornir/core/task.py", line 174, in run
    raise NornirSubTaskError(task=run_task, result=r)
nornir.core.exceptions.NornirSubTaskError: Subtask: send_configs (failed)


2024-04-15 11:33:06,171 -  nornir.core -     INFO -        run() - Running task 'rollback_configs' with args {'backup_folder': '/root/cn6000_automation/runbooks/backup_configs/20240415_113247'} on 7 hosts
2024-04-15 11:33:06,172 - nornir.core.task -    ERROR -      start() - Host 'C-TOK-1-3': task 'rollback_configs' failed with traceback:
Traceback (most recent call last):
  File "/root/cn6000_automation/.venv/lib/python3.8/site-packages/nornir/core/task.py", line 99, in start
    r = self.task(self, **self.params)
TypeError: rollback_configs() got an unexpected keyword argument 'backup_folder'

2024-04-15 11:33:06,172 - nornir.core.task -    ERROR -      start() - Host 'D-LAG-3-2': task 'rollback_configs' failed with traceback:
Traceback (most recent call last):
  File "/root/cn6000_automation/.venv/lib/python3.8/site-packages/nornir/core/task.py", line 99, in start
    r = self.task(self, **self.params)
TypeError: rollback_configs() got an unexpected keyword argument 'backup_folder'

2024-04-15 11:33:06,173 - nornir.core.task -    ERROR -      start() - Host 'D-LAG-2-3': task 'rollback_configs' failed with traceback:
Traceback (most recent call last):
  File "/root/cn6000_automation/.venv/lib/python3.8/site-packages/nornir/core/task.py", line 99, in start
    r = self.task(self, **self.params)
TypeError: rollback_configs() got an unexpected keyword argument 'backup_folder'

2024-04-15 11:33:06,173 - nornir.core.task -    ERROR -      start() - Host 'C-LAG-1-4': task 'rollback_configs' failed with traceback:
Traceback (most recent call last):
  File "/root/cn6000_automation/.venv/lib/python3.8/site-packages/nornir/core/task.py", line 99, in start
    r = self.task(self, **self.params)
TypeError: rollback_configs() got an unexpected keyword argument 'backup_folder'

2024-04-15 11:33:06,173 - nornir.core.task -    ERROR -      start() - Host 'LEAF-HQ-1-2': task 'rollback_configs' failed with traceback:
Traceback (most recent call last):
  File "/root/cn6000_automation/.venv/lib/python3.8/site-packages/nornir/core/task.py", line 99, in start
    r = self.task(self, **self.params)
TypeError: rollback_configs() got an unexpected keyword argument 'backup_folder'

2024-04-15 11:33:06,173 - nornir.core.task -    ERROR -      start() - Host 'LEAF-HQ-2-3': task 'rollback_configs' failed with traceback:
Traceback (most recent call last):
  File "/root/cn6000_automation/.venv/lib/python3.8/site-packages/nornir/core/task.py", line 99, in start
    r = self.task(self, **self.params)
TypeError: rollback_configs() got an unexpected keyword argument 'backup_folder'

2024-04-15 11:33:06,174 - nornir.core.task -    ERROR -      start() - Host 'LEAF-HQ-3-4': task 'rollback_configs' failed with traceback:
Traceback (most recent call last):
  File "/root/cn6000_automation/.venv/lib/python3.8/site-packages/nornir/core/task.py", line 99, in start
    r = self.task(self, **self.params)
TypeError: rollback_configs() got an unexpected keyword argument 'backup_folder'

2024-04-15 11:33:42,413 -  nornir.core -     INFO -        run() - Running task 'connection_test' with args {} on 7 hosts
2024-04-15 11:33:43,878 -  nornir.core -     INFO -        run() - Running task 'backup_current_configs' with args {'backup_folder': 'backup_configs/20240415_113342'} on 7 hosts
2024-04-15 11:33:46,105 -  nornir.core -     INFO -        run() - Running task 'load_variables' with args {'nr': <nornir.core.Nornir object at 0x7f9affef62e0>} on 7 hosts
2024-04-15 11:39:05,220 -  nornir.core -     INFO -        run() - Running task 'connection_test' with args {} on 7 hosts
2024-04-15 11:39:06,605 -  nornir.core -     INFO -        run() - Running task 'backup_current_configs' with args {'backup_folder': 'backup_configs/20240415_113905'} on 7 hosts
2024-04-15 11:39:09,392 -  nornir.core -     INFO -        run() - Running task 'load_variables' with args {'nr': <nornir.core.Nornir object at 0x7f4b1cbb7f70>} on 7 hosts
2024-04-15 11:46:23,960 -  nornir.core -     INFO -        run() - Running task 'connection_test' with args {} on 7 hosts
2024-04-15 11:46:25,326 -  nornir.core -     INFO -        run() - Running task 'backup_current_configs' with args {'backup_folder': 'backup_configs/20240415_114623'} on 7 hosts
2024-04-15 11:46:27,578 -  nornir.core -     INFO -        run() - Running task 'load_variables' with args {'nr': <nornir.core.Nornir object at 0x7fe0cc0e62e0>} on 7 hosts
2024-04-15 11:49:43,525 -  nornir.core -     INFO -        run() - Running task 'connection_test' with args {} on 7 hosts
2024-04-15 11:49:44,878 -  nornir.core -     INFO -        run() - Running task 'backup_current_configs' with args {'backup_folder': 'backup_configs/20240415_114943'} on 7 hosts
2024-04-15 11:49:47,139 -  nornir.core -     INFO -        run() - Running task 'load_variables' with args {'nr': <nornir.core.Nornir object at 0x7fba3901af70>} on 7 hosts
2024-04-15 11:51:58,218 -  nornir.core -     INFO -        run() - Running task 'connection_test' with args {} on 7 hosts
2024-04-15 11:51:59,600 -  nornir.core -     INFO -        run() - Running task 'backup_current_configs' with args {'backup_folder': 'backup_configs/20240415_115158'} on 7 hosts
2024-04-15 11:52:01,882 -  nornir.core -     INFO -        run() - Running task 'load_variables' with args {'nr': <nornir.core.Nornir object at 0x7f32cb291f70>} on 7 hosts
